Workbook

Sheet Main_Data
A1: Country | B1: Region | C1: Year | D1: GDP_per_Capita | E1: Health_Exp_% | F1: Life_Expectancy | G1: Population | H1: Healthcare_Index | I1: Unemployment_Rate | J1: Literacy_Rate | K1: Covid_Impact | L1: Continent
A2: India | B2: South Asia | C2: 2021 | D2: 28697 | E2: 10.7 | F2: 68 | G2: 320755470 | H2: 65 | I2: 21 | J2: 87 | K2: 43 | L2: Asia
A3: USA | B3: North America | C3: 2021 | D3: 9328 | E3: 9.1 | F3: 61 | G3: 779975845 | H3: 54 | I3: 7.5 | J3: 86 | K3: 51 | L3: North America
A4: Germany | B4: Europe | C4: 2022 | D4: 32915 | E4: 7.3 | F4: 81 | G4: 1024677989 | H4: 84 | I4: 22 | J4: 86 | K4: 88 | L4: Europe
A5: Brazil | B5: South America | C5: 2022 | D5: 48330 | E5: 11.3 | F5: 73 | G5: 11982489 | H5: 75 | I5: 16.3 | J5: 70 | K5: 60 | L5: South America
A6: China | B6: East Asia | C6: 2021 | D6: 46701 | E6: 6.7 | F6: 84 | G6: 1398599595 | H6: 66 | I6: 18 | J6: 94 | K6: 87 | L6: Asia
A7: UK | B7: Europe | C7: 2020 | D7: 53760 | E7: 13.9 | F7: 65 | G7: 225142920 | H7: 80 | I7: 4 | J7: 92 | K7: 39 | L7: Europe
A8: Canada | B8: North America | C8: 2021 | D8: 49493 | E8: 11.8 | F8: 76 | G8: 1025519857 | H8: 87 | I8: 10 | J8: 81 | K8: 42 | L8: North America
A9: Australia | B9: Oceania | C9: 2020 | D9: 33504 | E9: 9.9 | F9: 71 | G9: 997430905 | H9: 84 | I9: 6.4 | J9: 96 | K9: 64 | L9: Oceania
A10: Japan | B10: East Asia | C10: 2020 | D10: 54027 | E10: 16.2 | F10: 78 | G10: 579162748 | H10: 76 | I10: 21.2 | J10: 88 | K10: 47 | L10: Asia
A11: South Africa | B11: Africa | C11: 2020 | D11: 49580 | E11: 11.3 | F11: 65 | G11: 1150916965 | H11: 94 | I11: 7.7 | J11: 76 | K11: 65 | L11: Africa
A12: India | B12: South Asia | C12: 2022 | D12: 12017 | E12: 6.9 | F12: 82 | G12: 583736500 | H12: 50 | I12: 13 | J12: 71 | K12: 72 | L12: Asia
A13: USA | B13: North America | C13: 2020 | D13: 32580 | E13: 8.7 | F13: 64 | G13: 1491550777 | H13: 66 | I13: 2.3 | J13: 84 | K13: 87 | L13: North America
... A501: South Africa | B501: Africa | C501: 2020 | D501: 51044 | E501: 15.9 | F501: 82 | G501: 476370662 | H501: 94 | I501: 21.9 | J501: 87 | K501: 44 | L501: Africa

Sheet Clean_Data
A1: Country | B1: Region | C1: Year | D1: GDP_per_Capita | E1: Health_Exp_% | F1: Life_Expectancy | G1: Population | H1: Healthcare_Index | I1: Unemployment_Rate | J1: Literacy_Rate | K1: Covid_Impact | L1: Continent | M1: Clean_Country | N1: Clean_Region | O1: Health_Category | P1: Economic_Category | Q1: Quality
A2: =Main_Data!A2 -> India | B2: =Main_Data!B2 -> South Asia | C2: =Main_Data!C2 -> 2021 | D2: =Main_Data!D2 -> 28697 | E2: =Main_Data!E2 -> 10.7 | F2: =Main_Data!F2 -> 68 | G2: =Main_Data!G2 -> 320755470 | H2: =Main_Data!H2 -> 65 | ... L2: =Main_Data!L2 -> Asia | M2: =PROPER(TRIM(Main_Data!A2)) -> India | N2: =PROPER(TRIM(Main_Data!B2)) -> South Asia | O2: {=_xlfn.IFS(F2>=80,"Very High",F2>=70,"High",F2>=60,"Medium",TRUE,"Low")} -> Medium | P2: {=_xlfn.IFS(D2>=40000,"High Income",D2>=15000,"Middle Income",TRUE,"Low Income")} -> Middle Income | Q2: =IF(COUNTIFS(A:A,A2,C:C,C2)>1,"Duplicate","OK") -> Duplicate
A3: =Main_Data!A3 -> USA | B3: =Main_Data!B3 -> North America | C3: =Main_Data!C3 -> 2021 | D3: =Main_Data!D3 -> 9328 | E3: =Main_Data!E3 -> 9.1 | F3: =Main_Data!F3 -> 61 | G3: =Main_Data!G3 -> 779975845 | H3: =Main_Data!H3 -> 54 | ... L3: =Main_Data!L3 -> North America | M3: =PROPER(TRIM(Main_Data!A3)) -> Usa | N3: =PROPER(TRIM(Main_Data!B3)) -> North America | O3: {=_xlfn.IFS(F3>=80,"Very High",F3>=70,"High",F3>=60,"Medium",TRUE,"Low")} -> Medium | P3: {=_xlfn.IFS(D3>=40000,"High Income",D3>=15000,"Middle Income",TRUE,"Low Income")} -> Low Income | Q3: =IF(COUNTIFS(A:A,A3,C:C,C3)>1,"Duplicate","OK") -> Duplicate
A4: =Main_Data!A4 -> Germany | B4: =Main_Data!B4 -> Europe | C4: =Main_Data!C4 -> 2022 | D4: =Main_Data!D4 -> 32915 | E4: =Main_Data!E4 -> 7.3 | F4: =Main_Data!F4 -> 81 | G4: =Main_Data!G4 -> 1024677989 | H4: =Main_Data!H4 -> 84 | ... L4: =Main_Data!L4 -> Europe | M4: =PROPER(TRIM(Main_Data!A4)) -> Germany | N4: =PROPER(TRIM(Main_Data!B4)) -> Europe | O4: {=_xlfn.IFS(F4>=80,"Very High",F4>=70,"High",F4>=60,"Medium",TRUE,"Low")} -> Very High | P4: {=_xlfn.IFS(D4>=40000,"High Income",D4>=15000,"Middle Income",TRUE,"Low Income")} -> Middle Income | Q4: =IF(COUNTIFS(A:A,A4,C:C,C4)>1,"Duplicate","OK") -> Duplicate
A5: =Main_Data!A5 -> Brazil | B5: =Main_Data!B5 -> South America | C5: =Main_Data!C5 -> 2022 | D5: =Main_Data!D5 -> 48330 | E5: =Main_Data!E5 -> 11.3 | F5: =Main_Data!F5 -> 73 | G5: =Main_Data!G5 -> 11982489 | H5: =Main_Data!H5 -> 75 | ... L5: =Main_Data!L5 -> South America | M5: =PROPER(TRIM(Main_Data!A5)) -> Brazil | N5: =PROPER(TRIM(Main_Data!B5)) -> South America | O5: {=_xlfn.IFS(F5>=80,"Very High",F5>=70,"High",F5>=60,"Medium",TRUE,"Low")} -> High | P5: {=_xlfn.IFS(D5>=40000,"High Income",D5>=15000,"Middle Income",TRUE,"Low Income")} -> High Income | Q5: =IF(COUNTIFS(A:A,A5,C:C,C5)>1,"Duplicate","OK") -> Duplicate
A6: =Main_Data!A6 -> China | B6: =Main_Data!B6 -> East Asia | C6: =Main_Data!C6 -> 2021 | D6: =Main_Data!D6 -> 46701 | E6: =Main_Data!E6 -> 6.7 | F6: =Main_Data!F6 -> 84 | G6: =Main_Data!G6 -> 1398599595 | H6: =Main_Data!H6 -> 66 | ... L6: =Main_Data!L6 -> Asia | M6: =PROPER(TRIM(Main_Data!A6)) -> China | N6: =PROPER(TRIM(Main_Data!B6)) -> East Asia | O6: {=_xlfn.IFS(F6>=80,"Very High",F6>=70,"High",F6>=60,"Medium",TRUE,"Low")} -> Very High | P6: {=_xlfn.IFS(D6>=40000,"High Income",D6>=15000,"Middle Income",TRUE,"Low Income")} -> High Income | Q6: =IF(COUNTIFS(A:A,A6,C:C,C6)>1,"Duplicate","OK") -> Duplicate
A7: =Main_Data!A7 -> UK | B7: =Main_Data!B7 -> Europe | C7: =Main_Data!C7 -> 2020 | D7: =Main_Data!D7 -> 53760 | E7: =Main_Data!E7 -> 13.9 | F7: =Main_Data!F7 -> 65 | G7: =Main_Data!G7 -> 225142920 | H7: =Main_Data!H7 -> 80 | ... L7: =Main_Data!L7 -> Europe | M7: =PROPER(TRIM(Main_Data!A7)) -> Uk | N7: =PROPER(TRIM(Main_Data!B7)) -> Europe | O7: {=_xlfn.IFS(F7>=80,"Very High",F7>=70,"High",F7>=60,"Medium",TRUE,"Low")} -> Medium | P7: {=_xlfn.IFS(D7>=40000,"High Income",D7>=15000,"Middle Income",TRUE,"Low Income")} -> High Income | Q7: =IF(COUNTIFS(A:A,A7,C:C,C7)>1,"Duplicate","OK") -> Duplicate
A8: =Main_Data!A8 -> Canada | B8: =Main_Data!B8 -> North America | C8: =Main_Data!C8 -> 2021 | D8: =Main_Data!D8 -> 49493 | E8: =Main_Data!E8 -> 11.8 | F8: =Main_Data!F8 -> 76 | G8: =Main_Data!G8 -> 1025519857 | H8: =Main_Data!H8 -> 87 | ... L8: =Main_Data!L8 -> North America | M8: =PROPER(TRIM(Main_Data!A8)) -> Canada | N8: =PROPER(TRIM(Main_Data!B8)) -> North America | O8: {=_xlfn.IFS(F8>=80,"Very High",F8>=70,"High",F8>=60,"Medium",TRUE,"Low")} -> High | P8: {=_xlfn.IFS(D8>=40000,"High Income",D8>=15000,"Middle Income",TRUE,"Low Income")} -> High Income | Q8: =IF(COUNTIFS(A:A,A8,C:C,C8)>1,"Duplicate","OK") -> Duplicate
A9: =Main_Data!A9 -> Australia | B9: =Main_Data!B9 -> Oceania | C9: =Main_Data!C9 -> 2020 | D9: =Main_Data!D9 -> 33504 | E9: =Main_Data!E9 -> 9.9 | F9: =Main_Data!F9 -> 71 | G9: =Main_Data!G9 -> 997430905 | H9: =Main_Data!H9 -> 84 | ... L9: =Main_Data!L9 -> Oceania | M9: =PROPER(TRIM(Main_Data!A9)) -> Australia | N9: =PROPER(TRIM(Main_Data!B9)) -> Oceania | O9: {=_xlfn.IFS(F9>=80,"Very High",F9>=70,"High",F9>=60,"Medium",TRUE,"Low")} -> High | P9: {=_xlfn.IFS(D9>=40000,"High Income",D9>=15000,"Middle Income",TRUE,"Low Income")} -> Middle Income | Q9: =IF(COUNTIFS(A:A,A9,C:C,C9)>1,"Duplicate","OK") -> Duplicate
A10: =Main_Data!A10 -> Japan | B10: =Main_Data!B10 -> East Asia | C10: =Main_Data!C10 -> 2020 | D10: =Main_Data!D10 -> 54027 | E10: =Main_Data!E10 -> 16.2 | F10: =Main_Data!F10 -> 78 | G10: =Main_Data!G10 -> 579162748 | H10: =Main_Data!H10 -> 76 | ... L10: =Main_Data!L10 -> Asia | M10: =PROPER(TRIM(Main_Data!A10)) -> Japan | N10: =PROPER(TRIM(Main_Data!B10)) -> East Asia | O10: {=_xlfn.IFS(F10>=80,"Very High",F10>=70,"High",F10>=60,"Medium",TRUE,"Low")} -> High | P10: {=_xlfn.IFS(D10>=40000,"High Income",D10>=15000,"Middle Income",TRUE,"Low Income")} -> High Income | Q10: =IF(COUNTIFS(A:A,A10,C:C,C10)>1,"Duplicate","OK") -> Duplicate
A11: =Main_Data!A11 -> South Africa | B11: =Main_Data!B11 -> Africa | C11: =Main_Data!C11 -> 2020 | D11: =Main_Data!D11 -> 49580 | E11: =Main_Data!E11 -> 11.3 | F11: =Main_Data!F11 -> 65 | G11: =Main_Data!G11 -> 1150916965 | H11: =Main_Data!H11 -> 94 | ... L11: =Main_Data!L11 -> Africa | M11: =PROPER(TRIM(Main_Data!A11)) -> South Africa | N11: =PROPER(TRIM(Main_Data!B11)) -> Africa | O11: {=_xlfn.IFS(F11>=80,"Very High",F11>=70,"High",F11>=60,"Medium",TRUE,"Low")} -> Medium | P11: {=_xlfn.IFS(D11>=40000,"High Income",D11>=15000,"Middle Income",TRUE,"Low Income")} -> High Income | Q11: =IF(COUNTIFS(A:A,A11,C:C,C11)>1,"Duplicate","OK") -> Duplicate
A12: =Main_Data!A12 -> India | B12: =Main_Data!B12 -> South Asia | C12: =Main_Data!C12 -> 2022 | D12: =Main_Data!D12 -> 12017 | E12: =Main_Data!E12 -> 6.9 | F12: =Main_Data!F12 -> 82 | G12: =Main_Data!G12 -> 583736500 | H12: =Main_Data!H12 -> 50 | ... L12: =Main_Data!L12 -> Asia | M12: =PROPER(TRIM(Main_Data!A12)) -> India | N12: =PROPER(TRIM(Main_Data!B12)) -> South Asia | O12: {=_xlfn.IFS(F12>=80,"Very High",F12>=70,"High",F12>=60,"Medium",TRUE,"Low")} -> Very High | P12: {=_xlfn.IFS(D12>=40000,"High Income",D12>=15000,"Middle Income",TRUE,"Low Income")} -> Low Income | Q12: =IF(COUNTIFS(A:A,A12,C:C,C12)>1,"Duplicate","OK") -> Duplicate
A13: =Main_Data!A13 -> USA | B13: =Main_Data!B13 -> North America | C13: =Main_Data!C13 -> 2020 | D13: =Main_Data!D13 -> 32580 | E13: =Main_Data!E13 -> 8.7 | F13: =Main_Data!F13 -> 64 | G13: =Main_Data!G13 -> 1491550777 | H13: =Main_Data!H13 -> 66 | ... L13: =Main_Data!L13 -> North America | M13: =PROPER(TRIM(Main_Data!A13)) -> Usa | N13: =PROPER(TRIM(Main_Data!B13)) -> North America | O13: {=_xlfn.IFS(F13>=80,"Very High",F13>=70,"High",F13>=60,"Medium",TRUE,"Low")} -> Medium | P13: {=_xlfn.IFS(D13>=40000,"High Income",D13>=15000,"Middle Income",TRUE,"Low Income")} -> Middle Income | Q13: =IF(COUNTIFS(A:A,A13,C:C,C13)>1,"Duplicate","OK") -> Duplicate
... A501: =Main_Data!A501 -> South Africa | B501: =Main_Data!B501 -> Africa | C501: =Main_Data!C501 -> 2020 | D501: =Main_Data!D501 -> 51044 | E501: =Main_Data!E501 -> 15.9 | F501: =Main_Data!F501 -> 82 | G501: =Main_Data!G501 -> 476370662 | H501: =Main_Data!H501 -> 94 | ... L501: =Main_Data!L501 -> Africa | M501: =PROPER(TRIM(Main_Data!A501)) -> South Africa | N501: =PROPER(TRIM(Main_Data!B501)) -> Africa | O501: {=_xlfn.IFS(F501>=80,"Very High",F501>=70,"High",F501>=60,"Medium",TRUE,"Low")} -> Very High | P501: {=_xlfn.IFS(D501>=40000,"High Income",D501>=15000,"Middle Income",TRUE,"Low Income")} -> High Income | Q501: =IF(COUNTIFS(A:A,A501,C:C,C501)>1,"Duplicate","OK") -> Duplicate

Sheet Validation
A1: Country_List | B1: Region_List | C1: Year_List | D1: Continent_List
A2: {=_xlfn.UNIQUE(Main_Data!A2:A501)} -> India | B2: {=_xlfn.UNIQUE(Main_Data!B2:B501)} -> South Asia | C2: {=_xlfn.UNIQUE(Main_Data!C2:C501)} -> 2021 | D2: {=_xlfn.UNIQUE(Main_Data!L2:L501)} -> Asia
A3: USA | B3: North America | C3: 2022 | D3: North America
A4: Germany | B4: Europe | C4: 2020 | D4: Europe
A5: Brazil | B5: South America | D5: South America
A6: China | B6: East Asia | D6: Oceania
A7: UK | B7: Oceania | D7: Africa
A8: Canada | B8: Africa
A9: Australia
A10: Japan
A11: South Africa

Sheet VLookup_Tables
A1: Country | B1: Fetched_Continent | C1: Population | D1: Covid_Impact
A2: =Main_Data!A2 -> India | B2: =VLOOKUP(A2,Main_Data!A:B,2,FALSE) -> South Asia | C2: =VLOOKUP(A2,Main_Data!A1:L501,7,FALSE) -> 320755470 | D2: =VLOOKUP(A2,Main_Data!A1:L501,11,FALSE) -> 43
A3: =Main_Data!A3 -> USA | B3: =VLOOKUP(A3,Main_Data!A:B,2,FALSE) -> North America | C3: =VLOOKUP(A3,Main_Data!A2:L502,7,FALSE) -> 779975845 | D3: =VLOOKUP(A3,Main_Data!A2:L502,11,FALSE) -> 51
A4: =Main_Data!A4 -> Germany | B4: =VLOOKUP(A4,Main_Data!A:B,2,FALSE) -> Europe | C4: =VLOOKUP(A4,Main_Data!A3:L503,7,FALSE) -> 1024677989 | D4: =VLOOKUP(A4,Main_Data!A3:L503,11,FALSE) -> 88
A5: =Main_Data!A5 -> Brazil | B5: =VLOOKUP(A5,Main_Data!A:B,2,FALSE) -> South America | C5: =VLOOKUP(A5,Main_Data!A4:L504,7,FALSE) -> 11982489 | D5: =VLOOKUP(A5,Main_Data!A4:L504,11,FALSE) -> 60
A6: =Main_Data!A6 -> China | B6: =VLOOKUP(A6,Main_Data!A:B,2,FALSE) -> East Asia | C6: =VLOOKUP(A6,Main_Data!A5:L505,7,FALSE) -> 1398599595 | D6: =VLOOKUP(A6,Main_Data!A5:L505,11,FALSE) -> 87
A7: =Main_Data!A7 -> UK | B7: =VLOOKUP(A7,Main_Data!A:B,2,FALSE) -> Europe | C7: =VLOOKUP(A7,Main_Data!A6:L506,7,FALSE) -> 225142920 | D7: =VLOOKUP(A7,Main_Data!A6:L506,11,FALSE) -> 39
A8: =Main_Data!A8 -> Canada | B8: =VLOOKUP(A8,Main_Data!A:B,2,FALSE) -> North America | C8: =VLOOKUP(A8,Main_Data!A7:L507,7,FALSE) -> 1025519857 | D8: =VLOOKUP(A8,Main_Data!A7:L507,11,FALSE) -> 42
A9: =Main_Data!A9 -> Australia | B9: =VLOOKUP(A9,Main_Data!A:B,2,FALSE) -> Oceania | C9: =VLOOKUP(A9,Main_Data!A8:L508,7,FALSE) -> 997430905 | D9: =VLOOKUP(A9,Main_Data!A8:L508,11,FALSE) -> 64
A10: =Main_Data!A10 -> Japan | B10: =VLOOKUP(A10,Main_Data!A:B,2,FALSE) -> East Asia | C10: =VLOOKUP(A10,Main_Data!A9:L509,7,FALSE) -> 579162748 | D10: =VLOOKUP(A10,Main_Data!A9:L509,11,FALSE) -> 47
A11: =Main_Data!A11 -> South Africa | B11: =VLOOKUP(A11,Main_Data!A:B,2,FALSE) -> Africa | C11: =VLOOKUP(A11,Main_Data!A10:L510,7,FALSE) -> 1150916965 | D11: =VLOOKUP(A11,Main_Data!A10:L510,11,FALSE) -> 65
A12: =Main_Data!A12 -> India | B12: =VLOOKUP(A12,Main_Data!A:B,2,FALSE) -> South Asia | C12: =VLOOKUP(A12,Main_Data!A11:L511,7,FALSE) -> 583736500 | D12: =VLOOKUP(A12,Main_Data!A11:L511,11,FALSE) -> 72
A13: =Main_Data!A13 -> USA | B13: =VLOOKUP(A13,Main_Data!A:B,2,FALSE) -> North America | C13: =VLOOKUP(A13,Main_Data!A12:L512,7,FALSE) -> 1491550777 | D13: =VLOOKUP(A13,Main_Data!A12:L512,11,FALSE) -> 87
... A200: =Main_Data!A200 -> Japan | B200: =VLOOKUP(A200,Main_Data!A:B,2,FALSE) -> East Asia | C200: =VLOOKUP(A200,Main_Data!A199:L699,7,FALSE) -> 1143301030 | D200: =VLOOKUP(A200,Main_Data!A199:L699,11,FALSE) -> 64

Sheet HLookup_Tables
A1: Country | B1: India | C1: USA | D1: Germany | E1: Brazil | F1: China
A2: GDP_per_Capita | B2: 35770.98 | C2: 37589.82 | D2: 39469.6 | E2: 34413.36 | F2: 37636.9
A3: Life_Expectancy | B3: 71.7 | C3: 70.14 | D3: 71.96 | E3: 73.58 | F3: 72.22
A4: Health_Exp_% | B4: 8.33 | C4: 10.532 | D4: 9.05 | E4: 9.432 | F4: 10.506
A9: Country | B9: GDP | C9: Life Expectancy | D9: Health Exp
A10: India | B10: =HLOOKUP(A10,$A$1:$F$4,2,FALSE) -> 35770.98 | C10: =HLOOKUP(A10,$A$1:$F$4,3,FALSE) -> 71.7 | D10: =HLOOKUP(A10,$A$1:$F$4,4,FALSE) -> 8.33
A11: USA | B11: =HLOOKUP(A11,$A$1:$F$4,2,FALSE) -> 37589.82 | C11: =HLOOKUP(A11,$A$1:$F$4,3,FALSE) -> 70.14 | D11: =HLOOKUP(A11,$A$1:$F$4,4,FALSE) -> 10.532
A12: Germany | B12: =HLOOKUP(A12,$A$1:$F$4,2,FALSE) -> 39469.6 | C12: =HLOOKUP(A12,$A$1:$F$4,3,FALSE) -> 71.96 | D12: =HLOOKUP(A12,$A$1:$F$4,4,FALSE) -> 9.05
A13: Brazil | B13: =HLOOKUP(A13,$A$1:$F$4,2,FALSE) -> 34413.36 | C13: =HLOOKUP(A13,$A$1:$F$4,3,FALSE) -> 73.58 | D13: =HLOOKUP(A13,$A$1:$F$4,4,FALSE) -> 9.432
A14: China | B14: =HLOOKUP(A14,$A$1:$F$4,2,FALSE) -> 37636.9 | C14: =HLOOKUP(A14,$A$1:$F$4,3,FALSE) -> 72.22 | D14: =HLOOKUP(A14,$A$1:$F$4,4,FALSE) -> 10.506

Sheet Shorting
A1: Country | B1: Region | C1: Year | D1: GDP_per_Capita | E1: Health_Exp_% | F1: Life_Expectancy | G1: Population | H1: Healthcare_Index | I1: Unemployment_Rate | J1: Literacy_Rate | K1: Covid_Impact | L1: Continent
A2: Canada | B2: North America | C2: 2022 | D2: 26756 | E2: 6.8 | F2: 71 | G2: 1499990158 | H2: 59 | I2: 18.5 | J2: 81 | K2: 33 | L2: North America
A3: Canada | B3: North America | C3: 2022 | D3: 58981 | E3: 8.7 | F3: 66 | G3: 1494679285 | H3: 54 | I3: 7.2 | J3: 93 | K3: 67 | L3: North America
A4: China | B4: East Asia | C4: 2022 | D4: 48794 | E4: 6.4 | F4: 64 | G4: 1494088218 | H4: 53 | I4: 25 | J4: 72 | K4: 76 | L4: Asia
A5: USA | B5: North America | C5: 2022 | D5: 63624 | E5: 6.7 | F5: 73 | G5: 1486862463 | H5: 70 | I5: 3.5 | J5: 98 | K5: 53 | L5: North America
A6: Australia | B6: Oceania | C6: 2022 | D6: 61238 | E6: 16.2 | F6: 67 | G6: 1484327543 | H6: 90 | I6: 20.6 | J6: 89 | K6: 33 | L6: Oceania
A7: China | B7: East Asia | C7: 2022 | D7: 2082 | E7: 11.6 | F7: 71 | G7: 1481031812 | H7: 91 | I7: 18.4 | J7: 90 | K7: 82 | L7: Asia
A8: China | B8: East Asia | C8: 2022 | D8: 43771 | E8: 4.3 | F8: 71 | G8: 1475110392 | H8: 58 | I8: 12.8 | J8: 70 | K8: 59 | L8: Asia
A9: India | B9: South Asia | C9: 2022 | D9: 6757 | E9: 10 | F9: 72 | G9: 1468227841 | H9: 91 | I9: 17.6 | J9: 80 | K9: 63 | L9: Asia
A10: China | B10: East Asia | C10: 2022 | D10: 22458 | E10: 11.1 | F10: 76 | G10: 1468157032 | H10: 56 | I10: 24.5 | J10: 78 | K10: 44 | L10: Asia
A11: Germany | B11: Europe | C11: 2022 | D11: 54167 | E11: 14.3 | F11: 64 | G11: 1443738440 | H11: 50 | I11: 15.4 | J11: 88 | K11: 85 | L11: Europe
A12: Brazil | B12: South America | C12: 2022 | D12: 24488 | E12: 3.8 | F12: 64 | G12: 1426244731 | H12: 91 | I12: 3.5 | J12: 93 | K12: 43 | L12: South America
A13: UK | B13: Europe | C13: 2022 | D13: 43245 | E13: 11.3 | F13: 61 | G13: 1412620642 | H13: 51 | I13: 24.3 | J13: 97 | K13: 49 | L13: Europe
... A501: Australia | B501: Oceania | C501: 2020 | D501: 18226 | E501: 13.3 | F501: 79 | G501: 10101523 | H501: 53 | I501: 11.5 | J501: 89 | K501: 45 | L501: Oceania

Sheet Filtering
A1: Country | B1: Region | C1: Year | D1: GDP_per_Capita | E1: Health_Exp_% | F1: Life_Expectancy | G1: Population | H1: Healthcare_Index | I1: Unemployment_Rate | J1: Literacy_Rate | K1: Covid_Impact | L1: Continent
A2: India | B2: South Asia | C2: 2021 | D2: 28697 | E2: 10.7 | F2: 68 | G2: 320755470 | H2: 65 | I2: 21 | J2: 87 | K2: 43 | L2: Asia
A3: USA | B3: North America | C3: 2021 | D3: 9328 | E3: 9.1 | F3: 61 | G3: 779975845 | H3: 54 | I3: 7.5 | J3: 86 | K3: 51 | L3: North America
A4: Germany | B4: Europe | C4: 2022 | D4: 32915 | E4: 7.3 | F4: 81 | G4: 1024677989 | H4: 84 | I4: 22 | J4: 86 | K4: 88 | L4: Europe
A5: Brazil | B5: South America | C5: 2022 | D5: 48330 | E5: 11.3 | F5: 73 | G5: 11982489 | H5: 75 | I5: 16.3 | J5: 70 | K5: 60 | L5: South America
A6: China | B6: East Asia | C6: 2021 | D6: 46701 | E6: 6.7 | F6: 84 | G6: 1398599595 | H6: 66 | I6: 18 | J6: 94 | K6: 87 | L6: Asia
A7: UK | B7: Europe | C7: 2020 | D7: 53760 | E7: 13.9 | F7: 65 | G7: 225142920 | H7: 80 | I7: 4 | J7: 92 | K7: 39 | L7: Europe
A8: Canada | B8: North America | C8: 2021 | D8: 49493 | E8: 11.8 | F8: 76 | G8: 1025519857 | H8: 87 | I8: 10 | J8: 81 | K8: 42 | L8: North America
A9: Australia | B9: Oceania | C9: 2020 | D9: 33504 | E9: 9.9 | F9: 71 | G9: 997430905 | H9: 84 | I9: 6.4 | J9: 96 | K9: 64 | L9: Oceania
A10: Japan | B10: East Asia | C10: 2020 | D10: 54027 | E10: 16.2 | F10: 78 | G10: 579162748 | H10: 76 | I10: 21.2 | J10: 88 | K10: 47 | L10: Asia
A11: South Africa | B11: Africa | C11: 2020 | D11: 49580 | E11: 11.3 | F11: 65 | G11: 1150916965 | H11: 94 | I11: 7.7 | J11: 76 | K11: 65 | L11: Africa
A12: India | B12: South Asia | C12: 2022 | D12: 6757 | E12: 10 | F12: 72 | G12: 1468227841 | H12: 91 | I12: 17.6 | J12: 80 | K12: 63 | L12: Asia
A13: USA | B13: North America | C13: 2020 | D13: 32580 | E13: 8.7 | F13: 64 | G13: 1491550777 | H13: 66 | I13: 2.3 | J13: 84 | K13: 87 | L13: North America
... A501: South Africa | B501: Africa | C501: 2020 | D501: 51044 | E501: 15.9 | F501: 82 | G501: 476370662 | H501: 94 | I501: 21.9 | J501: 87 | K501: 44 | L501: Africa

Sheet Conditional Formating
A1: Country | B1: Region | C1: Year | D1: GDP_per_Capita | E1: Health_Exp_% | F1: Life_Expectancy | G1: Population | H1: Healthcare_Index | I1: Unemployment_Rate | J1: Literacy_Rate | K1: Covid_Impact | L1: Continent
A2: India | B2: South Asia | C2: 2021 | D2: 28697 | E2: 10.7 | F2: 68 | G2: 320755470 | H2: 65 | I2: 21 | J2: 87 | K2: 43 | L2: Asia
A3: USA | B3: North America | C3: 2021 | D3: 9328 | E3: 9.1 | F3: 61 | G3: 779975845 | H3: 54 | I3: 7.5 | J3: 86 | K3: 51 | L3: North America
A4: Germany | B4: Europe | C4: 2022 | D4: 32915 | E4: 7.3 | F4: 81 | G4: 1024677989 | H4: 84 | I4: 22 | J4: 86 | K4: 88 | L4: Europe
A5: Brazil | B5: South America | C5: 2022 | D5: 48330 | E5: 11.3 | F5: 73 | G5: 11982489 | H5: 75 | I5: 16.3 | J5: 70 | K5: 60 | L5: South America
A6: China | B6: East Asia | C6: 2021 | D6: 46701 | E6: 6.7 | F6: 84 | G6: 1398599595 | H6: 66 | I6: 18 | J6: 94 | K6: 87 | L6: Asia
A7: UK | B7: Europe | C7: 2020 | D7: 53760 | E7: 13.9 | F7: 65 | G7: 225142920 | H7: 80 | I7: 4 | J7: 92 | K7: 39 | L7: Europe
A8: Canada | B8: North America | C8: 2021 | D8: 49493 | E8: 11.8 | F8: 76 | G8: 1025519857 | H8: 87 | I8: 10 | J8: 81 | K8: 42 | L8: North America
A9: Australia | B9: Oceania | C9: 2020 | D9: 33504 | E9: 9.9 | F9: 71 | G9: 997430905 | H9: 84 | I9: 6.4 | J9: 96 | K9: 64 | L9: Oceania
A10: Japan | B10: East Asia | C10: 2020 | D10: 54027 | E10: 16.2 | F10: 78 | G10: 579162748 | H10: 76 | I10: 21.2 | J10: 88 | K10: 47 | L10: Asia
A11: South Africa | B11: Africa | C11: 2020 | D11: 49580 | E11: 11.3 | F11: 65 | G11: 1150916965 | H11: 94 | I11: 7.7 | J11: 76 | K11: 65 | L11: Africa
A12: India | B12: South Asia | C12: 2022 | D12: 12017 | E12: 6.9 | F12: 82 | G12: 583736500 | H12: 50 | I12: 13 | J12: 71 | K12: 72 | L12: Asia
A13: USA | B13: North America | C13: 2020 | D13: 32580 | E13: 8.7 | F13: 64 | G13: 1491550777 | H13: 66 | I13: 2.3 | J13: 84 | K13: 87 | L13: North America
... A501: South Africa | B501: Africa | C501: 2020 | D501: 51044 | E501: 15.9 | F501: 82 | G501: 476370662 | H501: 94 | I501: 21.9 | J501: 87 | K501: 44 | L501: Africa

Sheet Analysis
A1: Country | B1: Avg_GDP | C1: Avg_Life | D1: Avg_HealthExp
A2: India | B2: =AVERAGEIF(Clean_Data!A:A,A2,Clean_Data!D:D) -> 35770.98 | C2: =AVERAGEIF(Clean_Data!A:A,A2,Clean_Data!F:F) -> 71.7 | D2: =AVERAGEIF(Clean_Data!A:A,A2,Clean_Data!E:E) -> 8.838
A3: USA | B3: =AVERAGEIF(Clean_Data!A:A,A3,Clean_Data!D:D) -> 37589.82 | C3: =AVERAGEIF(Clean_Data!A:A,A3,Clean_Data!F:F) -> 70.14 | D3: =AVERAGEIF(Clean_Data!A:A,A3,Clean_Data!E:E) -> 10.532
A4: Germany | B4: =AVERAGEIF(Clean_Data!A:A,A4,Clean_Data!D:D) -> 39469.6 | C4: =AVERAGEIF(Clean_Data!A:A,A4,Clean_Data!F:F) -> 71.96 | D4: =AVERAGEIF(Clean_Data!A:A,A4,Clean_Data!E:E) -> 9.05
A5: Brazil | B5: =AVERAGEIF(Clean_Data!A:A,A5,Clean_Data!D:D) -> 34413.36 | C5: =AVERAGEIF(Clean_Data!A:A,A5,Clean_Data!F:F) -> 73.58 | D5: =AVERAGEIF(Clean_Data!A:A,A5,Clean_Data!E:E) -> 9.432
A6: China | B6: =AVERAGEIF(Clean_Data!A:A,A6,Clean_Data!D:D) -> 37636.9 | C6: =AVERAGEIF(Clean_Data!A:A,A6,Clean_Data!F:F) -> 72.22 | D6: =AVERAGEIF(Clean_Data!A:A,A6,Clean_Data!E:E) -> 10.506
A8: Region | B8: Average_GDP
A9: Africa | B9: =AVERAGEIFS(Main_Data!D:D,Main_Data!L:L,A9) -> 35281.68
A10: Asia | B10: =AVERAGEIFS(Main_Data!D:D,Main_Data!L:L,A10) -> 36245.72
A11: Europe | B11: =AVERAGEIFS(Main_Data!D:D,Main_Data!L:L,A11) -> 38347.44
A12: North America | B12: =AVERAGEIFS(Main_Data!D:D,Main_Data!L:L,A12) -> 37229.07
A13: Oceania | B13: =AVERAGEIFS(Main_Data!D:D,Main_Data!L:L,A13) -> 34481.5
A14: South America | B14: =AVERAGEIFS(Main_Data!D:D,Main_Data!L:L,A14) -> 34413.36

Sheet Pivot_Health_GDP
A1: Row Labels | B1: Sum of GDP_per_Capita
A2: Australia
A3: 2020 | B3: 492919
A4: 2021 | B4: 573910
A5: 2022 | B5: 657246
A6: Brazil
A7: 2020 | B7: 441583
A8: 2021 | B8: 644737
A9: 2022 | B9: 634348
A10: Canada
A11: 2020 | B11: 728199
A12: 2021 | B12: 511629
A13: 2022 | B13: 603588
A14: China
A15: 2020 | B15: 625711
A16: 2021 | B16: 661898
A17: 2022 | B17: 594236
A18: Germany
A19: 2020 | B19: 695658
A20: 2021 | B20: 636996
A21: 2022 | B21: 640826
A22: India
A23: 2020 | B23: 598330
A24: 2021 | B24: 776896
A25: 2022 | B25: 413323
A26: Japan
A27: 2020 | B27: 887602
A28: 2021 | B28: 426357
A29: 2022 | B29: 452505
A30: South Africa
A31: 2020 | B31: 897526
A32: 2021 | B32: 413466
A33: 2022 | B33: 453092
A34: UK
A35: 2020 | B35: 649718
A36: 2021 | B36: 477606
A37: 2022 | B37: 733940
A38: USA
A39: 2020 | B39: 936614
A40: 2021 | B40: 605308
...

Sheet Pivot_Region
A1: Row Labels | B1: Covid_Impact
A2: Australia
A3: Oceania | B3: 3025
A4: Brazil
A5: South America | B5: 3129
A6: Canada
A7: North America | B7: 3005
A8: China
A9: East Asia | B9: 3040
A10: Germany
A11: Europe | B11: 3081
A12: India
A13: South Asia | B13: 2942
A14: Japan
A15: East Asia | B15: 2981
A16: South Africa
A17: Africa | B17: 2835
A18: UK
A19: Europe | B19: 2998
A20: USA
A21: North America | B21: 3062
A22: Total Covid Impact | B22: 30098

Sheet Pivot Chart
A1: Region | B1: Avg_GDP
A2: East Asia | B2: =AVERAGEIF(Main_Data!B:B,A2,Main_Data!D:D) -> 36483.09
A3: South Asia | B3: =AVERAGEIF(Main_Data!B:B,A3,Main_Data!D:D) -> 35770.98
A4: Europe | B4: =AVERAGEIF(Main_Data!B:B,A4,Main_Data!D:D) -> 38347.44
A5: Africa | B5: =AVERAGEIF(Main_Data!B:B,A5,Main_Data!D:D) -> 35281.68
A6: North America | B6: =AVERAGEIF(Main_Data!B:B,A6,Main_Data!D:D) -> 37229.07
A7: South America | B7: =AVERAGEIF(Main_Data!B:B,A7,Main_Data!D:D) -> 34413.36
A8: Oceania | B8: =AVERAGEIF(Main_Data!B:B,A8,Main_Data!D:D) -> 34481.5

Sheet Dashboard
A1: GLOBAL HEALTH & ECONOMIC ANALYTICS DASHBOARD
B3: Avg GDP | C3: Avg Life Expectancy | D3: Total Population | E3: Max GDP
B4: =AVERAGE(Clean_Data!D:D) -> 36406.672 | C4: =AVERAGE(Clean_Data!F:F) -> 72.286 | D4: =SUM(Clean_Data!G:G) -> 388443294685 | E4: =MAX(Clean_Data!D:D) -> 69904
